<robot xmlns:xacro="http://www.ros.org/wiki/xacro" name="diffrobot">

<xacro:include filename="$(find diffrobot_description)/urdf/diffrobot.gazebo"/>  /*plugin*/

<link name="robot_footprint">
</link>

<joint name="robot_footprint_joint" type="fixed">
    <parent link="robot_footprint"/>
    <child link="base_link"/>
</joint>
    
<link name="base_link">
    <inertial>
        <origin xyz="0.0 0.0 0.0" rpy="0.0 0.0 0.0"/>
        <mass value="5.0"/>
        <inertia ixx="0.0" ixy="0.0" ixz="0.0" iyy="0.0" iyz="0.0" izz="0.0"/>
    </inertial>
    <visual name="base_link_visual">
        <origin xyz="0.0 0.0 0.0" rpy="0.0 0.0 0.0"/>
        <geometry>
            <box size="0.4 0.2 0.1"/>
        </geometry>
        <material name="">
            <color rgba="1.0 0.0 0.0 1.0"/>
            <texture filename=""/>
        </material>
    </visual>
    <collision>
        <origin xyz="0.0 0.0 0.0" rpy="0.0 0.0 0.0"/>
        <geometry>
            <box size="0.4 0.2 0.1"/>
        </geometry>
    </collision>
</link>

<link name="left_wheel">
    <inertial>
        <origin xyz="0.0 0.0 0.0" rpy="0.0 0.0 0.0"/>
        <mass value="1.0"/>
        <inertia ixx="0.0" ixy="0.0" ixz="0.0" iyy="0.0" iyz="0.0" izz="0.0"/>
    </inertial>
    <visual name="left_wheel_visual">
        <origin xyz="0.0 0.0 0.0" rpy="0.0 0.0 0.0"/>
        <geometry>
            <cylinder radius="0.1" length="0.05"/>
        </geometry>
        <material name="">
            <color rgba="0.0 1.0 0.0 1.0"/>
            <texture filename=""/>
        </material>
    </visual>
    <collision>
        <origin xyz="0.0 0.0 0.0" rpy="0.0 0.0 0.0"/>
        <geometry>
            <cylinder radius="0.1" length="0.05"/>
        </geometry>
    </collision>
</link>

<joint name="left_wheel_joint" type="continuous">
    <origin xyz="0.0 0.15 0.0" rpy="0.0 1.5705 1.5705"/>
    <parent link="base_link"/>
    <child link="left_wheel"/>
    <axis xyz="0.0 0.0 1.0"/>
    <limit lower="0.0" upper="0.0" effort="0.0" velocity="0.0"/>
</joint>

<link name="right_wheel">
    <inertial>
        <origin xyz="0.0 0.0 0.0" rpy="0.0 0.0 0.0"/>
        <mass value="1.0"/>
        <inertia ixx="0.0" ixy="0.0" ixz="0.0" iyy="0.0" iyz="0.0" izz="0.0"/>
    </inertial>
    <visual name="right_wheel_visual">
        <origin xyz="0.0 0.0 0.0" rpy="0.0 0.0 0.0"/>
        <geometry>
            <cylinder radius="0.1" length="0.05"/>
        </geometry>
        <material name="">
            <color rgba="0.0 1.0 0.0 1.0"/>
            <texture filename=""/>
        </material>
    </visual>
    <collision>
        <origin xyz="0.0 0.0 0.0" rpy="0.0 0.0 0.0"/>
        <geometry>
            <cylinder radius="0.1" length="0.05"/>
        </geometry>
    </collision>
</link>

<joint name="right_wheel_joint" type="continuous">
    <origin xyz="0.0 -0.15 0.0" rpy="0.0 1.5705 1.5705"/>
    <parent link="base_link"/>
    <child link="right_wheel"/>
    <axis xyz="0.0 0.0 1.0"/>
    <limit lower="0.0" upper="0.0" effort="0.0" velocity="0.0"/>
</joint>

<link name="front_caster">
    <inertial>
        <origin xyz="0.0 0.0 0.0" rpy="0.0 0.0 0.0"/>
        <mass value="0.1"/>
        <inertia ixx="0.0" ixy="0.0" ixz="0.0" iyy="0.0" iyz="0.0" izz="0.0"/>
    </inertial>
    <visual name="front_caster_visual">
        <origin xyz="0.0 0.0 0.0" rpy="0.0 0.0 0.0"/>
        <geometry>
            <sphere radius="0.0499"/>
        </geometry>
        <material name="">
            <color rgba="0.0 0.0 1.0 1.0"/>
            <texture filename=""/>
        </material>
    </visual>
    <collision>
        <origin xyz="0.0 0.0 0.0" rpy="0.0 0.0 0.0"/>
        <geometry>
            <sphere radius="0.0499"/>
        </geometry>
    </collision>
</link>

    <joint name="front_caster_joint" type="fixed">
        <origin xyz="0.15 0.0 -0.05" rpy="0.0 0.0 0.0"/>
        <parent link="base_link"/>
        <child link="front_caster"/>
        <axis xyz="0.0 0.0 0.0"/>
        <limit lower="0.0" upper="0.0" effort="0.0" velocity="0.0"/>
    </joint>

<link name="back_caster">
    <inertial>
        <origin xyz="0.0 0.0 0.0" rpy="0.0 0.0 0.0"/>
        <mass value="0.1"/>
        <inertia ixx="0.0" ixy="0.0" ixz="0.0" iyy="0.0" iyz="0.0" izz="0.0"/>
    </inertial>
    <visual name="back_caster_visual">
        <origin xyz="0.0 0.0 0.0" rpy="0.0 0.0 0.0"/>
        <geometry>
            <sphere radius="0.0499"/>
        </geometry>
        <material name="">
            <color rgba="0.0 0.0 1.0 1.0"/>
            <texture filename=""/>
        </material>
    </visual>
    <collision>
        <origin xyz="0.0 0.0 0.0" rpy="0.0 0.0 0.0"/>
        <geometry>
            <sphere radius="0.0499"/>
        </geometry>
    </collision>
</link>

    <joint name="back_caster_joint" type="fixed">
        <origin xyz="-0.15 0.0 -0.05" rpy="0.0 0.0 0.0"/>
        <parent link="base_link"/>
        <child link="back_caster"/>
        <axis xyz="0.0 0.0 0.0"/>
        <limit lower="0.0" upper="0.0" effort="0.0" velocity="0.0"/>
    </joint>

   

    <link name="lidar_link">
        <inertial>
            <origin xyz="0.0 0.0 0.0" rpy="0.0 0.0 0.0"/>
            <mass value="0.1"/>
            <inertia ixx="0.0" ixy="0.0" ixz="0.0" iyy="0.0" iyz="0.0" izz="0.0"/>
        </inertial>
        <visual name="lidar_link_visual">
            <origin xyz="0.0 0.0 0.0" rpy="0.0 0.0 0.0"/>
            <geometry>
              <mesh filename="package://diffrobot_description/meshes/lidar_link.STL"/>
            </geometry>
            <material name="">
                <color rgba="0.0 0.0 1.0 1.0"/>
                <texture filename=""/>
            </material>
        </visual>
        <collision>
            <origin xyz="0.0 0.0 0.0" rpy="0.0 0.0 0.0"/>
            <geometry>
                 <box size="0.1 0.1 0.1"/>
            </geometry>
        </collision>
    </link>

    <joint name="lidar_joint" type="fixed">
         <origin xyz="0.01 0.0 0.12" rpy="1.5708 0.0 1.5708"/>
        <parent link="base_link"/>
        <child link="lidar_link"/>
    </joint>

<link name="laser_data_link">
    
</link>

<joint name="laser_data_joint" type="fixed">
     <origin xyz="0.01 0.0 0.12" rpy="0.0 -1.5708 -1.5708"/>
    <parent link="lidar_link"/>
    <child link="laser_data_link"/>
</joint>



<link name="camera_link">
    <inertial>
        <origin xyz="0.0 0.0 0.0" rpy="0.0 0.0 0.0"/>
        <mass value="0.1"/>
        <inertia ixx="0.0" ixy="0.0" ixz="0.0" iyy="0.0" iyz="0.0" izz="0.0"/>
    </inertial>
    <visual name="camera_link_visual">
        <origin xyz="0.0 0.0 0.0" rpy="0.0 0.0 0.0"/>
        <geometry>
            <box size="0.1 0.1 0.1"/>
        </geometry>
        <material name="">
            <color rgba="0.0 1.0 0.0 1.0"/>
            <texture filename=""/>
        </material>
    </visual>
    <collision>
        <origin xyz="0.0 0.0 0.0" rpy="0.0 0.0 0.0"/>
        <geometry>
            <box size="0.1 0.1 0.1"/>
        </geometry>
    </collision>
</link>
<joint name="camera_joint" type="fixed">
   <origin xyz="0.17 0.0 0.12" rpy="0.0 0.0 0.0"/>
    <parent link="base_link"/>
    <child link="camera_link"/>
</joint>
</robot>
